<?xml version="1.0"?>
<robot name = "desherbor_ensta" xmlns:xacro="http://ros.org/wiki/xacro">

  <xacro:include filename="$(find desherbor_ensta)/urdf/robot_desherbor.wheels.xacro"/>
  <xacro:include filename="$(find desherbor_ensta)/urdf/robot.camera.xacro"/>
  <xacro:include filename="$(find desherbor_ensta)/urdf/robot.laser.xacro"/>
  <xacro:include filename="$(find desherbor_ensta)/urdf/robot.lidar.xacro"/>
  <xacro:include filename="$(find desherbor_ensta)/urdf/robot.IMU.xacro"/>

  <xacro:macro name="box_inertial" params="mass height width depth">
    <inertial>
      <mass value="${mass}" />
      <inertia ixx="${0.08*mass*(height*height + depth*depth)}" ixy="0.0" ixz="0.0" iyy="${0.08*mass*(width*width + depth*depth)}" iyz="0.0" izz="${0.08*mass*(width*width + height*height)}" />
    </inertial>
  </xacro:macro>

  <xacro:macro name="cylinder_inertial" params="length mass radius">
    <inertial>
      <mass value="${mass}"/>
      <inertia ixx = "${0.08*(mass)*(3*radius*radius + length*length)}" ixy="0.0" ixz="0.0" iyy="${0.08*(mass)*(3*radius*radius + length*length)}" iyz="0.0" izz="${0.5*mass*radius*radius}" />
    </inertial>
  </xacro:macro>

  <xacro:macro name="default_inertial" params="mass">
    <inertial>
      <mass value="${mass}"/>
      <inertia ixx="0.1" ixy="0.0" ixz="0.0" iyy="0.1" iyz="0.0" izz="0.1" />
    </inertial>
  </xacro:macro>


  <link name="base_link"/>

  <joint name="base_joint" type="fixed">
    <parent link="base_link"/>
    <child link="chassis"/>
    <origin xyz="0 0 0.01" rpy="0 0 0"/>
  </joint>

  <link name="chassis">
    <collision>
      <origin xyz="0 0 0.1" rpy="0 0 0"/>
      <geometry>
        <box size="0.3 0.1  0.1"/>
      </geometry>
    </collision>

    <visual>
      <origin xyz="0 0 0.1" rpy="0 0 0"/>
      <geometry>
        <box size="0.3 0.2 0.1"/>
      </geometry>
    </visual>
    <xacro:box_inertial mass="10.0" height="0.3" width="0.2" depth="0.1"/>
  </link>

  <link name="left_top_wheel">
    <collision>
      <origin xyz="0 0 0" rpy="0 1.5707 1.5707"/>
      <geometry>
        <cylinder radius="0.1" length="0.05"/>
      </geometry>
    </collision>
    <visual>
      <origin xyz="0 0 0" rpy="0 1.5707 1.5707"/>
      <geometry>
        <cylinder radius="0.1" length="0.05"/>
      </geometry>
    </visual>
    <xacro:cylinder_inertial mass="1" length="0.05" radius="0.1" />
  </link>

  <link name="right_top_wheel">
    <collision>
      <origin xyz="0 0 0" rpy="0 1.5707 1.5707"/>
      <geometry>
        <cylinder radius="0.1" length="0.05"/>
      </geometry>
    </collision>
    <visual>
      <origin xyz="0 0 0" rpy="0 1.5707 1.5707"/>
      <geometry>
        <cylinder radius="0.1" length="0.05"/>
      </geometry>
    </visual>
    <xacro:cylinder_inertial mass="1" length="0.05" radius="0.1" />
  </link>

  <link name="left_bottom_wheel">
    <collision>
      <origin xyz="0 0 0" rpy="0 1.5707 1.5707"/>
      <geometry>
        <cylinder radius="0.1" length="0.05"/>
      </geometry>
    </collision>
    <visual>
      <origin xyz="0 0 0" rpy="0 1.5707 1.5707"/>
      <geometry>
        <cylinder radius="0.1" length="0.05"/>
      </geometry>
    </visual>
    <xacro:cylinder_inertial mass="1" length="0.05" radius="0.1" />
  </link>

  <link name="right_bottom_wheel">
    <collision>
      <origin xyz="0 0 0" rpy="0 1.5707 1.5707"/>
      <geometry>
        <cylinder radius="0.1" length="0.05"/>
      </geometry>
    </collision>
    <visual>
      <origin xyz="0 0 0" rpy="0 1.5707 1.5707"/>
      <geometry>
        <cylinder radius="0.1" length="0.05"/>
      </geometry>
    </visual>
    <xacro:cylinder_inertial mass="1" length="0.05" radius="0.1" />
  </link>

  <joint type="revolute" name="left_top_wheel_hinge">
    <origin xyz="0.1 0.13 0.1" rpy="0 0 0"/>
    <child link="free_left"/>
    <parent link="chassis"/>
    <axis xyz="0 0 1"/>
    <limit effort="1000.0" lower="-0.78" upper="0.78" velocity="10.0" />
  </joint>

  <joint type="revolute" name="right_top_wheel_hinge">
    <origin xyz="0.1 -0.13 0.1" rpy="0 0 0"/>
    <child link="free_right"/>
    <parent link="chassis"/>
    <axis xyz="0 0 1"/>
    <limit effort="1000.0" lower="-0.78" upper="0.78" velocity="10.0" />
  </joint>

  <joint type="continuous" name="left_bottom_wheel_hinge">
    <origin xyz="-0.1 0.13 0.1" rpy="0 0 0"/>
    <child link="left_bottom_wheel"/>
    <parent link="chassis"/>
    <axis xyz="0 1 0"/>
  </joint>

  <joint type="continuous" name="right_bottom_wheel_hinge">
    <origin xyz="-0.1 -0.13 0.1" rpy="0 0 0"/>
    <child link="right_bottom_wheel"/>
    <parent link="chassis"/>
    <axis xyz="0 1 0"/>
  </joint>

  <joint type="continuous" name="free_right_top">
    <origin xyz="0 0 0" rpy="0 0 0"/>
    <child link="right_top_wheel"/>
    <parent link="free_right"/>
    <axis xyz="0 1 0"/>
  </joint>

  <joint type="continuous" name="free_left_top">
    <origin xyz="0 0 0" rpy="0 0 0"/>
    <child link="left_top_wheel"/>
    <parent link="free_left"/>
    <axis xyz="0 1 0"/>
  </joint>

  <link name="free_right">
    <visual>
      <origin xyz="0 0 0" rpy="0 0 0"/>
      <geometry>
        <cylinder radius="0.01" length="0.01"/>
      </geometry>
    </visual>
    <xacro:default_inertial mass="0.1"/>
  </link>
  <link name="free_left">
    <visual>
      <origin xyz="0 0 0" rpy="0 0 0"/>
      <geometry>
        <cylinder radius="0.01" length="0.01"/>
      </geometry>
    </visual>
    <xacro:default_inertial mass="0.1"/>
  </link>

  <link name="arm">
    <collision>
      <origin xyz="0.2 0 0.2" rpy="0 1.56 0"/>
      <geometry>
        <cylinder radius="0.01" length="0.3"/>
      </geometry>
    </collision>
    <visual>
      <origin xyz="0.2 0 0.2" rpy="0 1.56 0"/>
      <geometry>
        <cylinder radius="0.01" length="0.3"/>
      </geometry>
    </visual>
    <xacro:default_inertial mass=" 0.3"/>
  </link>

  <joint type="continuous" name="arm_hinge">
    <origin xyz="0 0 0" rpy="0 0 0"/>
    <child link="arm"/>
    <parent link="chassis"/>
    <axis xyz="0 0 1"/>
  </joint>

  <joint name="camera_joint" type="fixed">
    <parent link="chassis"/>
    <child link="camera"/>
    <origin xyz="0.1 0.0 0.1" rpy="0 0 0"/>
  </joint>


  <link name="laser">
    <collision>
      <origin xyz="0.16 0 0.095" rpy="0 0 1.5707"/>
      <geometry>
        <cylinder radius="0.025" length="0.017"/>
      </geometry>
    </collision>
    <visual>
      <origin xyz="0.16 0 0.095" rpy="0 0 1.5707"/>
      <geometry>
        <cylinder radius="0.0025" length="0.017"/>
      </geometry>
    </visual>
    <xacro:default_inertial mass="0.3"/>
  </link>

  <joint type="fixed" name="laser_hinge">
    <origin xyz="0.16 0 0.095" rpy="0 0 0"/>
    <child link="laser"/>
    <parent link="arm"/>
    <axis xyz="0 1 0"/>
  </joint>

  <link name="lidar">
    <visual>
      <origin xyz="0 0 0.075" rpy="0 0 0"/>
      <geometry>
        <cylinder radius="0.03" length="0.1"/>
      </geometry>
    </visual>
    <xacro:default_inertial mass="0.1"/>
  </link>

  <joint name="lidar_hinge" type="fixed">
    <child link="lidar"/>
    <parent link="arm"/>
    <origin xyz="0 0 0.075" rpy="0 0 0"/>
  </joint>

    <link name="camera">
    <visual>
      <geometry>
        <sphere radius="0.01"/>
      </geometry>
    </visual>
    <xacro:default_inertial mass="0.1"/>
  </link>

  <joint name="camera_hinge" type="fixed">
    <child link="camera"/>
    <parent link="arm"/>
    <origin xyz="0.2 0 0.1" rpy="0 0 0"/>
  </joint>

  <transmission name="trans_left_bottom_wheel">
    <type> transmission_interface/SimpleTransmission </type>
    <joint name="left_bottom_wheel_hinge">
      <hardwareInterface> EffortJointInterface</hardwareInterface>
    </joint>
    <actuator name="bottom_wheel_actuator">
      <mechanicalReduction>10</mechanicalReduction>
      <hardwareInterface>EffortJointInterface</hardwareInterface>
    </actuator>
  </transmission>

  <transmission name="trans_right_bottom_wheel">
    <type> transmission_interface/SimpleTransmission </type>
    <joint name="right_bottom_wheel_hinge">
      <hardwareInterface>EffortJointInterface</hardwareInterface>
    </joint>
    <actuator name="bottom_wheel_actuator">
      <mechanicalReduction>10</mechanicalReduction>
      <hardwareInterface>EffortJointInterface</hardwareInterface>
    </actuator>
  </transmission>

  <transmission name="trans_left_top_wheel">
    <type> transmission_interface/SimpleTransmission</type>
    <joint name="left_top_wheel_hinge">
      <hardwareInterface>EffortJointInterface</hardwareInterface>
    </joint>
    <actuator name="righttop_wheel_actuator">
      <mechanicalReduction>30</mechanicalReduction>
      <hardwareInterface>EffortJointInterface</hardwareInterface>
    </actuator>
  </transmission>

  <transmission name="trans_right_top_wheel">
    <type> transmission_interface/SimpleTransmission</type>
    <joint name="right_top_wheel_hinge">
      <hardwareInterface>EffortJointInterface</hardwareInterface>
    </joint>
    <actuator name="top_wheel_actuator">
      <mechanicalReduction>30</mechanicalReduction>
      <hardwareInterface>EffortJointInterface</hardwareInterface>
    </actuator>
  </transmission>

  <transmission name="trans_arm">
    <type> transmission_interface/SimpleTransmission</type>
    <joint name="arm_hinge">
      <hardwareInterface>EffortJointInterface</hardwareInterface>
    </joint>
    <actuator name="arm_actuator">
      <mechanicalReduction>30</mechanicalReduction>
      <hardwareInterface>EffortJointInterface</hardwareInterface>
    </actuator>
  </transmission>

  <gazebo>
    <plugin name="gazebo_ros_control" filename="libgazebo_ros_control.so">
      <robotNamespace>/desherbor_ensta</robotNamespace>
    </plugin>
  </gazebo>

  <link name="imu_link">
    <visual>
      <origin xyz="0 0 0.1" rpy="0 0 0"/>
      <geometry>
        <cylinder radius="0.01" length="0.01"/>
      </geometry>
      <collision>
        <geometry>
          <cylinder radius="0.001" length="0.001"/>
        </geometry>
      </collision>
    </visual>
    <xacro:default_inertial mass="0.1"/>
  </link>

  <joint name="imu_link_hinge" type="fixed">
    <child link="imu_link"/>
    <parent link="chassis"/>
    <origin xyz="0 0 0.1" rpy="0 0 0"/>
  </joint>

</robot>
